# 2023년 5월 1일(월)

---

### Today I Learned 

- [iOS-Swift] 에러 처리(Error Handling)

---

## 에러를 던지는 함수를 처리하는 함수

### 에러 정의

```swift
// 에러정의
enum SomeError: Error {
    case aError
}

// 에러를 던지는 함수 정의 (무조건 에러를 던진다고 가정)
func throwingFunc() throws {
    throw SomeError.aError
}

// 에러의 처리
do {
    try throwingFunc()
} catch {
    print(error)
}
```

### 일반적인 함수로 처리

```swift
// 함수 내부에서 do-catch문으로 에러를 처리
// 즉, 발생한 에러를 catch블럭에서 받아서 알맞은 처리
func handleError() {
    do {
        try throwingFunc()
    } catch {
        print(error)
    }
}

handleError()
```

### 1- throwing함수로 에러 다시 던지기

```swift
/**====================================================
 - 함수 내에서 에러를 직접처리하지 못하는 경우, 에러를 다시 던질 수 있음
 ====================================================**/
func handleError1() throws {
    //do {
    try throwingFunc()
    //}                     // catch블럭이 없어도 에러를 밖으로 던질 수 있음 ⭐️
}

do {
    try handleError1()   // 에러를 받아서 처리 가능
} catch {
    print(error)
}
```

### 2 - rethrowing함수로 에러 다시 던지기(rethrows 키워드)

```swift
/**================================================================
 - 에러를 던지는 throwing함수를 파라미터로 받는 경우, 내부에서 다시 에러를 던지기 가능
 - rethrows키워드 필요 (Rethrowing메서드)
 ==================================================================**/

// 다시 에러를 던지는 함수(방법1)
func someFunction1(callback: () throws -> Void) rethrows {
    try callback()             // 에러를 다시 던짐(직접 던지지 못함)
    // throw (X)
}

// 다시 에러를 던지는 함수(방법2) - 에러변환
func someFunction2(callback: () throws -> Void) rethrows {
    enum ChangedError: Error {
        case cError
    }
    
    do {
        try callback()
    } catch {   // catch구문에서는 throw (O)
        throw ChangedError.cError    // 에러를 변환해서 다시 던짐
    }
}

// 실제 에러를 다시던지는(rethrowing)함수를 처리하는 부분
do {
    try someFunction1(callback: throwingFunc)
} catch {
    print(error)
}

do {
    try someFunction2(callback: throwingFunc)
} catch {
    print(error)
}
```